[2025-08-17 21:27:50.944] INFO     [MainThread] logger:info:366 - Connected to git repository: /Users/arif/Desktop/Bakalimm/Auto-Push-And-AI-Commit-Mesaj/.autocommit-pro
[2025-08-17 21:27:50.946] INFO     [MainThread] logger:info:366 - File monitoring callback registered
[2025-08-17 21:27:50.947] INFO     [MainThread] logger:info:366 - Scheduled tasks configured
[2025-08-17 21:27:50.948] INFO     [MainThread] logger:info:366 - AutoGitManager initialized for: /Users/arif/Desktop/Bakalimm/Auto-Push-And-AI-Commit-Mesaj/.autocommit-pro
[2025-08-17 21:27:50.949] INFO     [MainThread] logger:info:366 - ðŸš€ Starting AutoGitManager...
[2025-08-17 21:27:50.980] INFO     [MainThread] logger:info:366 - Repository status: Branch=main, Dirty=False
[2025-08-17 21:27:50.985] INFO     [MainThread] logger:info:366 - Scheduler thread started
[2025-08-17 21:27:50.986] SUCCESS  [MainThread] logger:success:370 - AutoGitManager started successfully!
[2025-08-17 21:34:38.015] INFO     [MainThread] logger:info:366 - Connected to git repository: /Users/arif/Desktop/Bakalimm/Auto-Push-And-AI-Commit-Mesaj/.autocommit-pro
[2025-08-17 21:34:38.018] INFO     [MainThread] logger:info:366 - File monitoring callback registered
[2025-08-17 21:34:38.019] INFO     [MainThread] logger:info:366 - Scheduled tasks configured
[2025-08-17 21:34:38.020] INFO     [MainThread] logger:info:366 - AutoGitManager initialized for: /Users/arif/Desktop/Bakalimm/Auto-Push-And-AI-Commit-Mesaj/.autocommit-pro
[2025-08-17 21:34:38.022] INFO     [MainThread] logger:info:366 - ðŸš€ Starting AutoGitManager...
[2025-08-17 21:34:38.059] INFO     [MainThread] logger:info:366 - Repository status: Branch=main, Dirty=False
[2025-08-17 21:34:38.064] INFO     [MainThread] logger:info:366 - Scheduler thread started
[2025-08-17 21:34:38.065] SUCCESS  [MainThread] logger:success:370 - AutoGitManager started successfully!
[2025-08-17 21:34:52.581] INFO     [MainThread] logger:info:366 - ðŸ›‘ Stopping AutoGitManager...
[2025-08-17 21:34:52.598] INFO     [MainThread] logger:info:366 - Final push before shutdown...
[2025-08-17 21:34:52.602] INFO     [MainThread] logger:info:366 - Starting auto-push to remote repository
[2025-08-17 21:34:52.637] WARNING  [MainThread] logger:warning:374 - Auto-push failed: No commits to push
[2025-08-17 21:34:52.643] SUCCESS  [MainThread] logger:success:370 - AutoGitManager stopped successfully!
[2025-08-17 21:35:08.068] DEBUG    [ThreadPoolExecutor-0_0] logger:debug:362 - Processing 1 file changes
[2025-08-17 21:35:08.698] INFO     [MainThread] logger:info:366 - Connected to git repository: /Users/arif/Desktop/Bakalimm/Auto-Push-And-AI-Commit-Mesaj/.autocommit-pro
[2025-08-17 21:35:08.699] INFO     [MainThread] logger:info:366 - File monitoring callback registered
[2025-08-17 21:35:08.699] INFO     [MainThread] logger:info:366 - Scheduled tasks configured
[2025-08-17 21:35:08.699] INFO     [MainThread] logger:info:366 - AutoGitManager initialized for: /Users/arif/Desktop/Bakalimm/Auto-Push-And-AI-Commit-Mesaj/.autocommit-pro
[2025-08-17 21:35:38.075] DEBUG    [ThreadPoolExecutor-0_0] logger:debug:362 - Processing 1 file changes
[2025-08-17 21:39:27.446] INFO     [MainThread] logger:info:366 - Connected to git repository: /Users/arif/Desktop/Bakalimm/Auto-Push-And-AI-Commit-Mesaj/.autocommit-pro
[2025-08-17 21:39:27.447] INFO     [MainThread] logger:info:366 - File monitoring callback registered
[2025-08-17 21:39:27.448] INFO     [MainThread] logger:info:366 - Scheduled tasks configured
[2025-08-17 21:39:27.448] INFO     [MainThread] logger:info:366 - AutoGitManager initialized for: /Users/arif/Desktop/Bakalimm/Auto-Push-And-AI-Commit-Mesaj/.autocommit-pro
[2025-08-17 21:39:27.483] ERROR    [MainThread] logger:error:380 - Failed to create commit
Exception: Traceback (most recent call last):
  File "/Users/arif/Desktop/Bakalimm/Auto-Push-And-AI-Commit-Mesaj/.autocommit-pro/auto_git_manager.py", line 142, in commit
    if not self.repo.index.diff("HEAD"):
  File "/Users/arif/anaconda3/lib/python3.10/site-packages/git/index/base.py", line 1517, in diff
    other = self.repo.rev_parse(other)
  File "/Users/arif/anaconda3/lib/python3.10/site-packages/git/repo/fun.py", line 415, in rev_parse
    obj = name_to_object(repo, rev)
  File "/Users/arif/anaconda3/lib/python3.10/site-packages/git/repo/fun.py", line 202, in name_to_object
    raise BadName(name)
gitdb.exc.BadName: Ref 'HEAD' did not resolve to an object

[2025-08-17 21:39:30.576] DEBUG    [ThreadPoolExecutor-0_0] logger:debug:362 - Processing 1 file changes
[2025-08-17 21:39:30.581] INFO     [ThreadPoolExecutor-0_0] logger:info:366 - Starting auto-commit for 1 changed files
[2025-08-17 21:39:33.484] ERROR    [ThreadPoolExecutor-0_0] logger:error:380 - Failed to create commit
Exception: Traceback (most recent call last):
  File "/Users/arif/Desktop/Bakalimm/Auto-Push-And-AI-Commit-Mesaj/.autocommit-pro/auto_git_manager.py", line 142, in commit
    if not self.repo.index.diff("HEAD"):
  File "/Users/arif/anaconda3/lib/python3.10/site-packages/git/index/base.py", line 1517, in diff
    other = self.repo.rev_parse(other)
  File "/Users/arif/anaconda3/lib/python3.10/site-packages/git/repo/fun.py", line 415, in rev_parse
    obj = name_to_object(repo, rev)
  File "/Users/arif/anaconda3/lib/python3.10/site-packages/git/repo/fun.py", line 202, in name_to_object
    raise BadName(name)
gitdb.exc.BadName: Ref 'HEAD' did not resolve to an object

[2025-08-17 21:39:33.493] ERROR    [ThreadPoolExecutor-0_0] logger:error:380 - Auto-commit failed: Commit failed: Ref 'HEAD' did not resolve to an object
[2025-08-17 21:40:17.297] INFO     [MainThread] logger:info:366 - Connected to git repository: /Users/arif/Desktop/Bakalimm/Auto-Push-And-AI-Commit-Mesaj/.autocommit-pro
[2025-08-17 21:40:17.299] INFO     [MainThread] logger:info:366 - File monitoring callback registered
[2025-08-17 21:40:17.301] INFO     [MainThread] logger:info:366 - Scheduled tasks configured
[2025-08-17 21:40:17.302] INFO     [MainThread] logger:info:366 - AutoGitManager initialized for: /Users/arif/Desktop/Bakalimm/Auto-Push-And-AI-Commit-Mesaj/.autocommit-pro
[2025-08-17 21:40:17.304] INFO     [MainThread] logger:info:366 - ðŸš€ Starting AutoGitManager...
[2025-08-17 21:40:17.337] INFO     [MainThread] logger:info:366 - Repository status: Branch=main, Dirty=False
[2025-08-17 21:40:17.343] INFO     [MainThread] logger:info:366 - Scheduler thread started
[2025-08-17 21:40:17.344] SUCCESS  [MainThread] logger:success:370 - AutoGitManager started successfully!
[2025-08-17 21:40:30.311] INFO     [MainThread] logger:info:366 - ðŸ›‘ Stopping AutoGitManager...
[2025-08-17 21:40:30.318] INFO     [MainThread] logger:info:366 - Committing pending changes before shutdown...
[2025-08-17 21:40:30.323] INFO     [MainThread] logger:info:366 - Starting auto-commit for 1 changed files
[2025-08-17 21:40:32.428] ERROR    [MainThread] logger:error:380 - Failed to create commit
Exception: Traceback (most recent call last):
  File "/Users/arif/Desktop/Bakalimm/Auto-Push-And-AI-Commit-Mesaj/.autocommit-pro/auto_git_manager.py", line 142, in commit
    if not self.repo.index.diff("HEAD"):
  File "/Users/arif/anaconda3/lib/python3.10/site-packages/git/index/base.py", line 1517, in diff
    other = self.repo.rev_parse(other)
  File "/Users/arif/anaconda3/lib/python3.10/site-packages/git/repo/fun.py", line 415, in rev_parse
    obj = name_to_object(repo, rev)
  File "/Users/arif/anaconda3/lib/python3.10/site-packages/git/repo/fun.py", line 202, in name_to_object
    raise BadName(name)
gitdb.exc.BadName: Ref 'HEAD' did not resolve to an object

[2025-08-17 21:40:32.438] ERROR    [MainThread] logger:error:380 - Auto-commit failed: Commit failed: Ref 'HEAD' did not resolve to an object
[2025-08-17 21:40:32.449] INFO     [MainThread] logger:info:366 - Final push before shutdown...
[2025-08-17 21:40:32.452] INFO     [MainThread] logger:info:366 - Starting auto-push to remote repository
[2025-08-17 21:40:32.489] WARNING  [MainThread] logger:warning:374 - Auto-push failed: No commits to push
[2025-08-17 21:40:32.493] SUCCESS  [MainThread] logger:success:370 - AutoGitManager stopped successfully!
[2025-08-17 21:40:35.727] INFO     [MainThread] logger:info:366 - ðŸ›‘ Stopping AutoGitManager...
[2025-08-17 21:40:35.739] DEBUG    [ThreadPoolExecutor-0_0] logger:debug:362 - Processing 1 file changes
[2025-08-17 21:40:35.759] INFO     [MainThread] logger:info:366 - Final push before shutdown...
[2025-08-17 21:40:35.774] INFO     [MainThread] logger:info:366 - Starting auto-push to remote repository
[2025-08-17 21:40:35.820] WARNING  [MainThread] logger:warning:374 - Auto-push failed: No commits to push
[2025-08-17 21:40:35.825] SUCCESS  [MainThread] logger:success:370 - AutoGitManager stopped successfully!
[2025-08-17 21:40:39.070] INFO     [MainThread] logger:info:366 - Connected to git repository: /Users/arif/Desktop/Bakalimm/Auto-Push-And-AI-Commit-Mesaj/.autocommit-pro
[2025-08-17 21:40:39.072] INFO     [MainThread] logger:info:366 - File monitoring callback registered
[2025-08-17 21:40:39.073] INFO     [MainThread] logger:info:366 - Scheduled tasks configured
[2025-08-17 21:40:39.075] INFO     [MainThread] logger:info:366 - AutoGitManager initialized for: /Users/arif/Desktop/Bakalimm/Auto-Push-And-AI-Commit-Mesaj/.autocommit-pro
[2025-08-17 21:40:39.076] INFO     [MainThread] logger:info:366 - ðŸš€ Starting AutoGitManager...
[2025-08-17 21:40:39.117] INFO     [MainThread] logger:info:366 - Repository status: Branch=main, Dirty=False
[2025-08-17 21:40:39.122] INFO     [MainThread] logger:info:366 - Scheduler thread started
[2025-08-17 21:40:39.123] SUCCESS  [MainThread] logger:success:370 - AutoGitManager started successfully!
[2025-08-17 21:42:43.638] INFO     [MainThread] logger:info:366 - ðŸ›‘ Stopping AutoGitManager...
[2025-08-17 21:42:43.657] INFO     [MainThread] logger:info:366 - Final push before shutdown...
[2025-08-17 21:42:43.662] INFO     [MainThread] logger:info:366 - Starting auto-push to remote repository
[2025-08-17 21:42:43.698] WARNING  [MainThread] logger:warning:374 - Auto-push failed: No commits to push
[2025-08-17 21:42:43.702] SUCCESS  [MainThread] logger:success:370 - AutoGitManager stopped successfully!
[2025-08-17 21:44:00.927] INFO     [MainThread] logger:info:366 - Connected to git repository: /Users/arif/Desktop/Bakalimm/Auto-Push-And-AI-Commit-Mesaj/.autocommit-pro
[2025-08-17 21:44:00.929] INFO     [MainThread] logger:info:366 - File monitoring callback registered
[2025-08-17 21:44:00.931] INFO     [MainThread] logger:info:366 - Scheduled tasks configured
[2025-08-17 21:44:00.932] INFO     [MainThread] logger:info:366 - AutoGitManager initialized for: /Users/arif/Desktop/Bakalimm/Auto-Push-And-AI-Commit-Mesaj/.autocommit-pro
[2025-08-17 21:44:00.934] INFO     [MainThread] logger:info:366 - ðŸš€ Starting AutoGitManager...
[2025-08-17 21:44:00.967] INFO     [MainThread] logger:info:366 - Repository status: Branch=main, Dirty=False
[2025-08-17 21:44:00.972] INFO     [MainThread] logger:info:366 - Scheduler thread started
[2025-08-17 21:44:00.973] SUCCESS  [MainThread] logger:success:370 - AutoGitManager started successfully!
[2025-08-17 21:45:49.432] INFO     [MainThread] logger:info:366 - ðŸ›‘ Stopping AutoGitManager...
[2025-08-17 21:45:49.449] INFO     [MainThread] logger:info:366 - Final push before shutdown...
[2025-08-17 21:45:49.454] INFO     [MainThread] logger:info:366 - Starting auto-push to remote repository
[2025-08-17 21:45:49.461] ERROR    [MainThread] logger:error:380 - Failed to push to remote
Exception: Traceback (most recent call last):
  File "/Users/arif/Desktop/Bakalimm/Auto-Push-And-AI-Commit-Mesaj/.autocommit-pro/auto_git_manager.py", line 169, in push
  File "/Users/arif/anaconda3/lib/python3.10/site-packages/git/repo/base.py", line 1054, in active_branch
    return self.head.reference
  File "/Users/arif/anaconda3/lib/python3.10/site-packages/git/refs/symbolic.py", line 506, in reference
    return self._get_reference()
  File "/Users/arif/anaconda3/lib/python3.10/site-packages/git/refs/symbolic.py", line 416, in _get_reference
    sha, target_ref_path = self._get_ref_info(self.repo, self.path)
  File "/Users/arif/anaconda3/lib/python3.10/site-packages/git/refs/symbolic.py", line 277, in _get_ref_info
    return cls._get_ref_info_helper(repo, ref_path)
  File "/Users/arif/anaconda3/lib/python3.10/site-packages/git/refs/symbolic.py", line 256, in _get_ref_info_helper
    raise ValueError("Reference at %r does not exist" % ref_path)
ValueError: Reference at 'HEAD' does not exist

[2025-08-17 21:45:49.469] WARNING  [MainThread] logger:warning:374 - Auto-push failed: Push failed: Reference at 'HEAD' does not exist
[2025-08-17 21:45:49.472] SUCCESS  [MainThread] logger:success:370 - AutoGitManager stopped successfully!
[2025-08-17 21:46:21.880] INFO     [MainThread] logger:info:366 - Connected to git repository: /Users/arif/Desktop/auto_commit_programs/Bakalimm/.autocommit-pro
[2025-08-17 21:46:21.881] INFO     [MainThread] logger:info:366 - File monitoring callback registered
[2025-08-17 21:46:21.882] INFO     [MainThread] logger:info:366 - Scheduled tasks configured
[2025-08-17 21:46:21.882] INFO     [MainThread] logger:info:366 - AutoGitManager initialized for: /Users/arif/Desktop/auto_commit_programs/Bakalimm/.autocommit-pro
[2025-08-17 21:46:34.576] INFO     [MainThread] logger:info:366 - Connected to git repository: /Users/arif/Desktop/auto_commit_programs/Bakalimm/.autocommit-pro
[2025-08-17 21:46:34.578] INFO     [MainThread] logger:info:366 - File monitoring callback registered
[2025-08-17 21:46:34.580] INFO     [MainThread] logger:info:366 - Scheduled tasks configured
[2025-08-17 21:46:34.581] INFO     [MainThread] logger:info:366 - AutoGitManager initialized for: /Users/arif/Desktop/auto_commit_programs/Bakalimm/.autocommit-pro
[2025-08-17 21:46:34.582] INFO     [MainThread] logger:info:366 - ðŸš€ Starting AutoGitManager...
[2025-08-17 21:46:34.617] INFO     [MainThread] logger:info:366 - Repository status: Branch=main, Dirty=False
[2025-08-17 21:46:34.623] INFO     [MainThread] logger:info:366 - Scheduler thread started
[2025-08-17 21:46:34.624] SUCCESS  [MainThread] logger:success:370 - AutoGitManager started successfully!
[2025-08-17 21:49:09.316] INFO     [MainThread] logger:info:366 - ðŸ›‘ Stopping AutoGitManager...
[2025-08-17 21:49:09.333] INFO     [MainThread] logger:info:366 - Final push before shutdown...
[2025-08-17 21:49:09.336] INFO     [MainThread] logger:info:366 - Starting auto-push to remote repository
[2025-08-17 21:49:09.372] WARNING  [MainThread] logger:warning:374 - Auto-push failed: No commits to push
[2025-08-17 21:49:09.377] SUCCESS  [MainThread] logger:success:370 - AutoGitManager stopped successfully!
[2025-08-17 21:49:52.266] INFO     [MainThread] logger:info:366 - Connected to git repository: /Users/arif/Desktop/auto_commit_programs/Bakalimm/.autocommit-pro
[2025-08-17 21:49:52.267] INFO     [MainThread] logger:info:366 - File monitoring callback registered
[2025-08-17 21:49:52.267] INFO     [MainThread] logger:info:366 - Scheduled tasks configured
[2025-08-17 21:49:52.267] INFO     [MainThread] logger:info:366 - AutoGitManager initialized for: /Users/arif/Desktop/auto_commit_programs/Bakalimm/.autocommit-pro
[2025-08-17 21:49:52.304] ERROR    [MainThread] logger:error:380 - Failed to create commit
Exception: Traceback (most recent call last):
  File "/Users/arif/Desktop/auto_commit_programs/Bakalimm/.autocommit-pro/auto_git_manager.py", line 142, in commit
    if not self.repo.index.diff("HEAD"):
  File "/Users/arif/anaconda3/lib/python3.10/site-packages/git/index/base.py", line 1517, in diff
    other = self.repo.rev_parse(other)
  File "/Users/arif/anaconda3/lib/python3.10/site-packages/git/repo/fun.py", line 415, in rev_parse
    obj = name_to_object(repo, rev)
  File "/Users/arif/anaconda3/lib/python3.10/site-packages/git/repo/fun.py", line 202, in name_to_object
    raise BadName(name)
gitdb.exc.BadName: Ref 'HEAD' did not resolve to an object

[2025-08-17 21:50:21.171] INFO     [MainThread] logger:info:366 - Connected to git repository: /Users/arif/Desktop/auto_commit_programs/Bakalimm/.autocommit-pro
[2025-08-17 21:50:21.172] INFO     [MainThread] logger:info:366 - File monitoring callback registered
[2025-08-17 21:50:21.172] INFO     [MainThread] logger:info:366 - Scheduled tasks configured
[2025-08-17 21:50:21.172] INFO     [MainThread] logger:info:366 - AutoGitManager initialized for: /Users/arif/Desktop/auto_commit_programs/Bakalimm/.autocommit-pro
[2025-08-17 21:52:07.631] INFO     [MainThread] logger:info:366 - Connected to git repository: /Users/arif/Desktop/auto_commit_programs/Bakalimm/.autocommit-pro
[2025-08-17 21:52:07.632] INFO     [MainThread] logger:info:366 - File monitoring callback registered
[2025-08-17 21:52:07.632] INFO     [MainThread] logger:info:366 - Scheduled tasks configured
[2025-08-17 21:52:07.632] INFO     [MainThread] logger:info:366 - AutoGitManager initialized for: /Users/arif/Desktop/auto_commit_programs/Bakalimm/.autocommit-pro
[2025-08-17 21:52:07.669] ERROR    [MainThread] logger:error:380 - Failed to create commit
Exception: Traceback (most recent call last):
  File "/Users/arif/Desktop/auto_commit_programs/Bakalimm/.autocommit-pro/auto_git_manager.py", line 142, in commit
    if not self.repo.index.diff("HEAD"):
  File "/Users/arif/anaconda3/lib/python3.10/site-packages/git/index/base.py", line 1517, in diff
    other = self.repo.rev_parse(other)
  File "/Users/arif/anaconda3/lib/python3.10/site-packages/git/repo/fun.py", line 415, in rev_parse
    obj = name_to_object(repo, rev)
  File "/Users/arif/anaconda3/lib/python3.10/site-packages/git/repo/fun.py", line 202, in name_to_object
    raise BadName(name)
gitdb.exc.BadName: Ref 'HEAD' did not resolve to an object

[2025-08-17 21:52:22.210] INFO     [MainThread] logger:info:366 - Connected to git repository: /Users/arif/Desktop/auto_commit_programs/Bakalimm/.autocommit-pro
[2025-08-17 21:52:22.211] INFO     [MainThread] logger:info:366 - File monitoring callback registered
[2025-08-17 21:52:22.211] INFO     [MainThread] logger:info:366 - Scheduled tasks configured
[2025-08-17 21:52:22.211] INFO     [MainThread] logger:info:366 - AutoGitManager initialized for: /Users/arif/Desktop/auto_commit_programs/Bakalimm/.autocommit-pro
[2025-08-17 21:55:42.774] INFO     [MainThread] logger:info:366 - Connected to git repository: /Users/arif/Desktop/auto_commit_programs/Bakalimm/.autocommit-pro
[2025-08-17 21:56:04.510] INFO     [MainThread] logger:info:366 - Connected to git repository: /Users/arif/Desktop/auto_commit_programs/Bakalimm/.autocommit-pro
[2025-08-17 21:56:20.632] INFO     [MainThread] logger:info:366 - Connected to git repository: /Users/arif/Desktop/auto_commit_programs/Bakalimm/.autocommit-pro
[2025-08-17 21:58:23.942] INFO     [MainThread] logger:info:366 - Connected to git repository: /Users/arif/Desktop/auto_commit_programs/Bakalimm
[2025-08-17 21:58:56.042] INFO     [MainThread] logger:info:366 - Connected to git repository: /Users/arif/Desktop/auto_commit_programs/Bakalimm
[2025-08-17 22:15:20.500] INFO     [MainThread] logger:info:366 - Connected to git repository: /Users/arif/Desktop/auto_commit_programs/Bakalimm
[2025-08-17 22:15:20.501] WARNING  [MainThread] logger:warning:374 - AI API key not found. AI commit messages will be disabled.
[2025-08-17 22:15:20.501] INFO     [MainThread] logger:info:366 - File monitoring callback registered
[2025-08-17 22:15:20.501] INFO     [MainThread] logger:info:366 - Scheduled tasks configured
[2025-08-17 22:15:20.502] INFO     [MainThread] logger:info:366 - AutoGitManager initialized for: /Users/arif/Desktop/auto_commit_programs/Bakalimm/.autocommit-pro
[2025-08-17 22:16:19.381] INFO     [MainThread] logger:info:366 - Connected to git repository: /Users/arif/Desktop/auto_commit_programs/Bakalimm
[2025-08-17 22:16:19.382] WARNING  [MainThread] logger:warning:374 - AI API key not found. AI commit messages will be disabled.
[2025-08-17 22:16:19.382] INFO     [MainThread] logger:info:366 - File monitoring callback registered
[2025-08-17 22:16:19.383] INFO     [MainThread] logger:info:366 - Scheduled tasks configured
[2025-08-17 22:16:19.383] INFO     [MainThread] logger:info:366 - AutoGitManager initialized for: /Users/arif/Desktop/auto_commit_programs/Bakalimm/.autocommit-pro
[2025-08-17 22:16:19.492] INFO     [MainThread] logger:info:366 - Added all files to staging area
[2025-08-17 22:16:19.522] SUCCESS  [MainThread] logger:success:370 - Created commit: fdebeeee - test: Add test file 6 for AutoCommit Pro testing...
[2025-08-17 22:21:26.744] INFO     [MainThread] logger:info:366 - Connected to git repository: /Users/arif/Desktop/auto_commit_programs/Bakalimm
[2025-08-17 22:21:26.746] INFO     [MainThread] logger:info:366 - File monitoring callback registered
[2025-08-17 22:21:26.748] INFO     [MainThread] logger:info:366 - Scheduled tasks configured
[2025-08-17 22:21:26.749] INFO     [MainThread] logger:info:366 - AutoGitManager initialized for: /Users/arif/Desktop/auto_commit_programs/Bakalimm/.autocommit-pro
[2025-08-17 22:21:26.750] INFO     [MainThread] logger:info:366 - ðŸš€ Starting AutoGitManager...
[2025-08-17 22:21:26.904] INFO     [MainThread] logger:info:366 - Repository status: Branch=main, Dirty=True
[2025-08-17 22:21:26.911] INFO     [MainThread] logger:info:366 - Scheduler thread started
[2025-08-17 22:21:26.912] SUCCESS  [MainThread] logger:success:370 - AutoGitManager started successfully!
[2025-08-17 22:21:57.702] INFO     [Thread-13 (scheduler_loop)] logger:info:366 - Periodic commit check: triggering auto-commit
[2025-08-17 22:21:57.706] DEBUG    [Thread-13 (scheduler_loop)] logger:debug:362 - No pending changes for auto-commit
[2025-08-17 22:22:02.836] INFO     [Thread-13 (scheduler_loop)] logger:info:366 - Periodic commit check: triggering auto-commit
[2025-08-17 22:22:02.841] DEBUG    [Thread-13 (scheduler_loop)] logger:debug:362 - No pending changes for auto-commit
[2025-08-17 22:22:03.542] INFO     [MainThread] logger:info:366 - ðŸ›‘ Stopping AutoGitManager...
[2025-08-17 22:22:03.552] INFO     [MainThread] logger:info:366 - Final push before shutdown...
[2025-08-17 22:22:03.556] INFO     [MainThread] logger:info:366 - Starting auto-push to remote repository
[2025-08-17 22:22:03.833] ERROR    [MainThread] logger:error:380 - Failed to get repository status
Exception: Traceback (most recent call last):
  File "/Users/arif/Desktop/auto_commit_programs/Bakalimm/.autocommit-pro/auto_git_manager.py", line 85, in get_status
    'staged_files': [item.a_path for item in self.repo.index.diff("HEAD")],
  File "/Users/arif/anaconda3/lib/python3.10/site-packages/git/index/base.py", line 1517, in diff
    other = self.repo.rev_parse(other)
  File "/Users/arif/anaconda3/lib/python3.10/site-packages/git/repo/fun.py", line 415, in rev_parse
    obj = name_to_object(repo, rev)
  File "/Users/arif/anaconda3/lib/python3.10/site-packages/git/repo/fun.py", line 205, in name_to_object
    return Object.new_from_sha(repo, hex_to_bin(hexsha))
  File "/Users/arif/anaconda3/lib/python3.10/site-packages/git/objects/base.py", line 149, in new_from_sha
    oinfo = repo.odb.info(sha1)
  File "/Users/arif/anaconda3/lib/python3.10/site-packages/git/db.py", line 41, in info
    hexsha, typename, size = self._git.get_object_header(bin_to_hex(binsha))
  File "/Users/arif/anaconda3/lib/python3.10/site-packages/git/cmd.py", line 1696, in get_object_header
    return self.__get_object_header(cmd, ref)
  File "/Users/arif/anaconda3/lib/python3.10/site-packages/git/cmd.py", line 1679, in __get_object_header
    cmd.stdin.flush()
BrokenPipeError: [Errno 32] Broken pipe

[2025-08-17 22:22:03.843] WARNING  [MainThread] logger:warning:374 - Auto-push failed: No commits to push
[2025-08-17 22:22:03.846] SUCCESS  [MainThread] logger:success:370 - AutoGitManager stopped successfully!
[2025-08-17 22:26:09.709] INFO     [MainThread] logger:info:366 - Connected to git repository: /Users/arif/Desktop/auto_commit_programs/Bakalimm
[2025-08-17 22:26:09.711] INFO     [MainThread] logger:info:366 - File monitoring callback registered
[2025-08-17 22:26:09.711] INFO     [MainThread] logger:info:366 - Scheduled tasks configured
[2025-08-17 22:26:09.711] INFO     [MainThread] logger:info:366 - AutoGitManager initialized for: /Users/arif/Desktop/auto_commit_programs/Bakalimm/.autocommit-pro
[2025-08-17 22:26:09.825] ERROR    [MainThread] logger:error:380 - Failed to add files to staging
Exception: Traceback (most recent call last):
  File "/Users/arif/Desktop/auto_commit_programs/Bakalimm/.autocommit-pro/auto_git_manager.py", line 120, in add_files
    self.repo.git.add(A=True)
  File "/Users/arif/anaconda3/lib/python3.10/site-packages/git/cmd.py", line 1003, in <lambda>
    return lambda *args, **kwargs: self._call_process(name, *args, **kwargs)
  File "/Users/arif/anaconda3/lib/python3.10/site-packages/git/cmd.py", line 1616, in _call_process
    return self.execute(call, **exec_kwargs)
  File "/Users/arif/anaconda3/lib/python3.10/site-packages/git/cmd.py", line 1406, in execute
    raise GitCommandError(redacted_command, status, stderr_value, stdout_value)
git.exc.GitCommandError: Cmd('git') failed due to: exit code(128)
  cmdline: git add -A
  stderr: 'error: '.autocommit-pro/' does not have a commit checked out
fatal: adding files failed'

[2025-08-17 22:26:22.451] INFO     [MainThread] logger:info:366 - Connected to git repository: /Users/arif/Desktop/auto_commit_programs/Bakalimm
[2025-08-17 22:26:22.452] INFO     [MainThread] logger:info:366 - File monitoring callback registered
[2025-08-17 22:26:22.452] INFO     [MainThread] logger:info:366 - Scheduled tasks configured
[2025-08-17 22:26:22.453] INFO     [MainThread] logger:info:366 - AutoGitManager initialized for: /Users/arif/Desktop/auto_commit_programs/Bakalimm/.autocommit-pro
[2025-08-17 22:26:22.563] ERROR    [MainThread] logger:error:380 - Failed to add files to staging
Exception: Traceback (most recent call last):
  File "/Users/arif/Desktop/auto_commit_programs/Bakalimm/.autocommit-pro/auto_git_manager.py", line 120, in add_files
    self.repo.git.add(A=True)
  File "/Users/arif/anaconda3/lib/python3.10/site-packages/git/cmd.py", line 1003, in <lambda>
    return lambda *args, **kwargs: self._call_process(name, *args, **kwargs)
  File "/Users/arif/anaconda3/lib/python3.10/site-packages/git/cmd.py", line 1616, in _call_process
    return self.execute(call, **exec_kwargs)
  File "/Users/arif/anaconda3/lib/python3.10/site-packages/git/cmd.py", line 1406, in execute
    raise GitCommandError(redacted_command, status, stderr_value, stdout_value)
git.exc.GitCommandError: Cmd('git') failed due to: exit code(128)
  cmdline: git add -A
  stderr: 'error: '.autocommit-pro/' does not have a commit checked out
fatal: adding files failed'

[2025-08-17 22:28:38.497] INFO     [MainThread] logger:info:366 - Connected to git repository: /Users/arif/Desktop/auto_commit_programs/Bakalimm
[2025-08-17 22:28:38.498] INFO     [MainThread] logger:info:366 - File monitoring callback registered
[2025-08-17 22:28:38.498] INFO     [MainThread] logger:info:366 - Scheduled tasks configured
[2025-08-17 22:28:38.498] INFO     [MainThread] logger:info:366 - AutoGitManager initialized for: /Users/arif/Desktop/auto_commit_programs/Bakalimm
[2025-08-17 22:35:02.394] INFO     [MainThread] logger:info:366 - Connected to git repository: /Users/arif/Desktop/auto_commit_programs/Bakalimm
[2025-08-17 22:35:02.395] INFO     [MainThread] logger:info:366 - File monitoring callback registered
[2025-08-17 22:35:02.395] INFO     [MainThread] logger:info:366 - Scheduled tasks configured
[2025-08-17 22:35:02.395] INFO     [MainThread] logger:info:366 - AutoGitManager initialized for: /Users/arif/Desktop/auto_commit_programs/Bakalimm
[2025-08-17 22:35:02.501] ERROR    [MainThread] logger:error:380 - Failed to add files to staging
Exception: Traceback (most recent call last):
  File "/Users/arif/Desktop/auto_commit_programs/Bakalimm/.autocommit-pro/auto_git_manager.py", line 120, in add_files
    self.repo.git.add(A=True)
  File "/Users/arif/anaconda3/lib/python3.10/site-packages/git/cmd.py", line 1003, in <lambda>
    return lambda *args, **kwargs: self._call_process(name, *args, **kwargs)
  File "/Users/arif/anaconda3/lib/python3.10/site-packages/git/cmd.py", line 1616, in _call_process
    return self.execute(call, **exec_kwargs)
  File "/Users/arif/anaconda3/lib/python3.10/site-packages/git/cmd.py", line 1406, in execute
    raise GitCommandError(redacted_command, status, stderr_value, stdout_value)
git.exc.GitCommandError: Cmd('git') failed due to: exit code(128)
  cmdline: git add -A
  stderr: 'error: '.autocommit-pro/' does not have a commit checked out
fatal: adding files failed'

[2025-08-17 22:35:20.485] INFO     [MainThread] logger:info:366 - Connected to git repository: /Users/arif/Desktop/auto_commit_programs/Bakalimm
[2025-08-17 22:35:20.486] INFO     [MainThread] logger:info:366 - File monitoring callback registered
[2025-08-17 22:35:20.486] INFO     [MainThread] logger:info:366 - Scheduled tasks configured
[2025-08-17 22:35:20.486] INFO     [MainThread] logger:info:366 - AutoGitManager initialized for: /Users/arif/Desktop/auto_commit_programs/Bakalimm
[2025-08-17 22:35:20.594] INFO     [MainThread] logger:info:366 - Added all files to staging area
[2025-08-17 22:35:20.624] SUCCESS  [MainThread] logger:success:370 - Created commit: 2e69ee1a - test: Test commit after adding .autocommit-pro to ...
[2025-08-17 22:36:10.318] INFO     [MainThread] logger:info:366 - Connected to git repository: /Users/arif/Desktop/auto_commit_programs/Bakalimm
[2025-08-17 22:36:10.319] INFO     [MainThread] logger:info:366 - File monitoring callback registered
[2025-08-17 22:36:10.319] INFO     [MainThread] logger:info:366 - Scheduled tasks configured
[2025-08-17 22:36:10.320] INFO     [MainThread] logger:info:366 - AutoGitManager initialized for: /Users/arif/Desktop/auto_commit_programs/Bakalimm
[2025-08-17 22:36:10.415] INFO     [MainThread] logger:info:366 - Added all files to staging area
[2025-08-17 22:36:10.443] SUCCESS  [MainThread] logger:success:370 - Created commit: 86722079 - test: Final test of working system...
[2025-08-17 22:37:14.555] INFO     [MainThread] logger:info:366 - Connected to git repository: /Users/arif/Desktop/auto_commit_programs/Bakalimm
[2025-08-17 22:37:14.556] INFO     [MainThread] logger:info:366 - File monitoring callback registered
[2025-08-17 22:37:14.556] INFO     [MainThread] logger:info:366 - Scheduled tasks configured
[2025-08-17 22:37:14.557] INFO     [MainThread] logger:info:366 - AutoGitManager initialized for: /Users/arif/Desktop/auto_commit_programs/Bakalimm
[2025-08-17 22:38:44.573] INFO     [MainThread] logger:info:366 - Connected to git repository: /Users/arif/Desktop/auto_commit_programs/Bakalimm
[2025-08-17 22:38:44.574] INFO     [MainThread] logger:info:366 - File monitoring callback registered
[2025-08-17 22:38:44.575] INFO     [MainThread] logger:info:366 - Scheduled tasks configured
[2025-08-17 22:38:44.575] INFO     [MainThread] logger:info:366 - AutoGitManager initialized for: /Users/arif/Desktop/auto_commit_programs/Bakalimm
[2025-08-17 22:39:46.964] INFO     [MainThread] logger:info:366 - Connected to git repository: /Users/arif/Desktop/auto_commit_programs/Bakalimm
[2025-08-17 22:39:46.965] INFO     [MainThread] logger:info:366 - File monitoring callback registered
[2025-08-17 22:39:46.966] INFO     [MainThread] logger:info:366 - Scheduled tasks configured
[2025-08-17 22:39:46.966] INFO     [MainThread] logger:info:366 - AutoGitManager initialized for: /Users/arif/Desktop/auto_commit_programs/Bakalimm
[2025-08-17 22:40:47.983] INFO     [MainThread] logger:info:366 - Connected to git repository: /Users/arif/Desktop/auto_commit_programs/Bakalimm
[2025-08-17 22:40:47.985] INFO     [MainThread] logger:info:366 - File monitoring callback registered
[2025-08-17 22:40:47.988] INFO     [MainThread] logger:info:366 - Scheduled tasks configured
[2025-08-17 22:40:47.989] INFO     [MainThread] logger:info:366 - AutoGitManager initialized for: /Users/arif/Desktop/auto_commit_programs/Bakalimm
[2025-08-17 22:40:47.992] CRITICAL [MainThread] logger:critical:386 - Failed to start AutoCommit Pro
Exception: Traceback (most recent call last):
  File "/Users/arif/Desktop/auto_commit_programs/Bakalimm/.autocommit-pro/main.py", line 332, in start
    self.manager.file_monitor.start()
AttributeError: 'FileMonitor' object has no attribute 'start'. Did you mean: 'stats'?

[2025-08-17 22:41:31.697] INFO     [MainThread] logger:info:366 - Connected to git repository: /Users/arif/Desktop/auto_commit_programs/Bakalimm
[2025-08-17 22:41:31.703] INFO     [MainThread] logger:info:366 - File monitoring callback registered
[2025-08-17 22:41:31.706] INFO     [MainThread] logger:info:366 - Scheduled tasks configured
[2025-08-17 22:41:31.708] INFO     [MainThread] logger:info:366 - AutoGitManager initialized for: /Users/arif/Desktop/auto_commit_programs/Bakalimm
[2025-08-17 22:41:31.712] CRITICAL [MainThread] logger:critical:386 - Failed to start AutoCommit Pro
Exception: Traceback (most recent call last):
  File "/Users/arif/Desktop/auto_commit_programs/Bakalimm/.autocommit-pro/main.py", line 332, in start
    self.manager.file_monitor.start()
AttributeError: 'FileMonitor' object has no attribute 'start'. Did you mean: 'stats'?

[2025-08-17 22:42:36.025] INFO     [MainThread] logger:info:366 - Connected to git repository: /Users/arif/Desktop/auto_commit_programs/Bakalimm
[2025-08-17 22:42:36.030] INFO     [MainThread] logger:info:366 - File monitoring callback registered
[2025-08-17 22:42:36.032] INFO     [MainThread] logger:info:366 - Scheduled tasks configured
[2025-08-17 22:42:36.033] INFO     [MainThread] logger:info:366 - AutoGitManager initialized for: /Users/arif/Desktop/auto_commit_programs/Bakalimm
[2025-08-17 22:42:36.041] INFO     [MainThread] logger:info:366 - ðŸš€ Starting AutoGitManager...
[2025-08-17 22:42:41.597] INFO     [MainThread] logger:info:366 - Repository status: Branch=main, Dirty=True
[2025-08-17 22:42:41.605] CRITICAL [MainThread] logger:critical:386 - Failed to start AutoGitManager
Exception: Traceback (most recent call last):
  File "/Users/arif/Desktop/auto_commit_programs/Bakalimm/.autocommit-pro/auto_git_manager.py", line 443, in start
    self.file_monitor.start_monitoring()
  File "/Users/arif/Desktop/auto_commit_programs/Bakalimm/.autocommit-pro/file_monitor.py", line 277, in start_monitoring
    self.observer.start()
  File "/Users/arif/anaconda3/lib/python3.10/site-packages/watchdog/observers/api.py", line 264, in start
    emitter.start()
  File "/Users/arif/anaconda3/lib/python3.10/site-packages/watchdog/utils/__init__.py", line 76, in start
    threading.Thread.start(self)
  File "/Users/arif/anaconda3/lib/python3.10/threading.py", line 930, in start
    raise RuntimeError("threads can only be started once")
RuntimeError: threads can only be started once

[2025-08-17 22:42:41.608] CRITICAL [MainThread] logger:critical:386 - Failed to start AutoCommit Pro
Exception: Traceback (most recent call last):
  File "/Users/arif/Desktop/auto_commit_programs/Bakalimm/.autocommit-pro/main.py", line 334, in start
    self.manager.start()
  File "/Users/arif/Desktop/auto_commit_programs/Bakalimm/.autocommit-pro/auto_git_manager.py", line 443, in start
    self.file_monitor.start_monitoring()
  File "/Users/arif/Desktop/auto_commit_programs/Bakalimm/.autocommit-pro/file_monitor.py", line 277, in start_monitoring
    self.observer.start()
  File "/Users/arif/anaconda3/lib/python3.10/site-packages/watchdog/observers/api.py", line 264, in start
    emitter.start()
  File "/Users/arif/anaconda3/lib/python3.10/site-packages/watchdog/utils/__init__.py", line 76, in start
    threading.Thread.start(self)
  File "/Users/arif/anaconda3/lib/python3.10/threading.py", line 930, in start
    raise RuntimeError("threads can only be started once")
RuntimeError: threads can only be started once

[2025-08-17 22:43:38.953] INFO     [MainThread] logger:info:366 - Connected to git repository: /Users/arif/Desktop/auto_commit_programs/Bakalimm
[2025-08-17 22:43:38.955] INFO     [MainThread] logger:info:366 - File monitoring callback registered
[2025-08-17 22:43:38.956] INFO     [MainThread] logger:info:366 - Scheduled tasks configured
[2025-08-17 22:43:38.958] INFO     [MainThread] logger:info:366 - AutoGitManager initialized for: /Users/arif/Desktop/auto_commit_programs/Bakalimm
[2025-08-17 22:43:38.959] INFO     [MainThread] logger:info:366 - ðŸš€ Starting AutoGitManager...
[2025-08-17 22:43:39.932] INFO     [MainThread] logger:info:366 - Repository status: Branch=main, Dirty=True
[2025-08-17 22:43:39.938] INFO     [MainThread] logger:info:366 - Scheduler thread started
[2025-08-17 22:43:39.940] SUCCESS  [MainThread] logger:success:370 - AutoGitManager started successfully!
[2025-08-17 22:44:13.021] DEBUG    [ThreadPoolExecutor-0_0] logger:debug:362 - Processing 1 file changes
[2025-08-17 22:45:33.170] DEBUG    [ThreadPoolExecutor-0_0] logger:debug:362 - Processing 1 file changes
[2025-08-17 22:45:45.189] DEBUG    [ThreadPoolExecutor-0_0] logger:debug:362 - Processing 1 file changes
[2025-08-17 22:45:59.222] DEBUG    [ThreadPoolExecutor-0_0] logger:debug:362 - Processing 1 file changes
[2025-08-17 22:46:00.123] DEBUG    [ThreadPoolExecutor-0_0] logger:debug:362 - Processing 5 file changes
[2025-08-17 22:46:00.135] INFO     [ThreadPoolExecutor-0_0] logger:info:366 - Starting auto-commit for 8 changed files
[2025-08-17 22:46:02.443] INFO     [ThreadPoolExecutor-0_0] logger:info:366 - Added all files to staging area
[2025-08-17 22:46:02.460] SUCCESS  [ThreadPoolExecutor-0_0] logger:success:370 - Created commit: 1fe713c2 - ```
YapÄ±landÄ±rma ve dokÃ¼mantasyon gÃ¼ncellemelerini...
[2025-08-17 22:46:02.465] SUCCESS  [ThreadPoolExecutor-0_0] logger:success:370 - Auto-commit successful: Commit created: 1fe713c2
[2025-08-17 22:46:02.470] INFO     [ThreadPoolExecutor-0_0] logger:info:366 - Starting auto-push to remote repository
[2025-08-17 22:46:03.454] WARNING  [ThreadPoolExecutor-0_0] logger:warning:374 - Auto-push failed: No commits to push
[2025-08-17 23:09:48.741] INFO     [MainThread] logger:info:366 - Connected to git repository: /Users/arif/Desktop/auto_commit_programs/hadi
[2025-08-17 23:09:48.746] INFO     [MainThread] logger:info:366 - File monitoring callback registered
[2025-08-17 23:09:48.748] INFO     [MainThread] logger:info:366 - Scheduled tasks configured
[2025-08-17 23:09:48.750] INFO     [MainThread] logger:info:366 - AutoGitManager initialized for: /Users/arif/Desktop/auto_commit_programs/hadi
[2025-08-17 23:09:48.751] INFO     [MainThread] logger:info:366 - ðŸš€ Starting AutoGitManager...
[2025-08-17 23:09:50.629] INFO     [MainThread] logger:info:366 - Repository status: Branch=main, Dirty=False
[2025-08-17 23:09:50.635] INFO     [MainThread] logger:info:366 - Scheduler thread started
[2025-08-17 23:09:50.637] SUCCESS  [MainThread] logger:success:370 - AutoGitManager started successfully!
[2025-08-17 23:10:04.770] DEBUG    [ThreadPoolExecutor-0_0] logger:debug:362 - Processing 1 file changes
[2025-08-17 23:10:04.777] INFO     [ThreadPoolExecutor-0_0] logger:info:366 - Starting auto-commit for 1 changed files
[2025-08-17 23:10:07.324] ERROR    [ThreadPoolExecutor-0_0] logger:error:380 - Failed to add files to staging
Exception: Traceback (most recent call last):
  File "/Users/arif/Desktop/auto_commit_programs/hadi/.autocommit-pro/auto_git_manager.py", line 120, in add_files
    self.repo.git.add(A=True)
  File "/Users/arif/anaconda3/lib/python3.10/site-packages/git/cmd.py", line 1003, in <lambda>
    return lambda *args, **kwargs: self._call_process(name, *args, **kwargs)
  File "/Users/arif/anaconda3/lib/python3.10/site-packages/git/cmd.py", line 1616, in _call_process
    return self.execute(call, **exec_kwargs)
  File "/Users/arif/anaconda3/lib/python3.10/site-packages/git/cmd.py", line 1406, in execute
    raise GitCommandError(redacted_command, status, stderr_value, stdout_value)
git.exc.GitCommandError: Cmd('git') failed due to: exit code(128)
  cmdline: git add -A
  stderr: 'error: '.autocommit-pro/' does not have a commit checked out
fatal: adding files failed'

[2025-08-17 23:10:07.333] ERROR    [ThreadPoolExecutor-0_0] logger:error:380 - Auto-commit failed: Failed to add files: Cmd('git') failed due to: exit code(128)
  cmdline: git add -A
  stderr: 'error: '.autocommit-pro/' does not have a commit checked out
fatal: adding files failed'
[2025-08-17 23:10:10.647] DEBUG    [ThreadPoolExecutor-0_0] logger:debug:362 - Processing 1 file changes
[2025-08-17 23:10:10.651] INFO     [ThreadPoolExecutor-0_0] logger:info:366 - Starting auto-commit for 2 changed files
[2025-08-17 23:10:12.547] ERROR    [ThreadPoolExecutor-0_0] logger:error:380 - Failed to add files to staging
Exception: Traceback (most recent call last):
  File "/Users/arif/Desktop/auto_commit_programs/hadi/.autocommit-pro/auto_git_manager.py", line 120, in add_files
    self.repo.git.add(A=True)
  File "/Users/arif/anaconda3/lib/python3.10/site-packages/git/cmd.py", line 1003, in <lambda>
    return lambda *args, **kwargs: self._call_process(name, *args, **kwargs)
  File "/Users/arif/anaconda3/lib/python3.10/site-packages/git/cmd.py", line 1616, in _call_process
    return self.execute(call, **exec_kwargs)
  File "/Users/arif/anaconda3/lib/python3.10/site-packages/git/cmd.py", line 1406, in execute
    raise GitCommandError(redacted_command, status, stderr_value, stdout_value)
git.exc.GitCommandError: Cmd('git') failed due to: exit code(128)
  cmdline: git add -A
  stderr: 'error: '.autocommit-pro/' does not have a commit checked out
fatal: adding files failed'

[2025-08-17 23:10:12.556] ERROR    [ThreadPoolExecutor-0_0] logger:error:380 - Auto-commit failed: Failed to add files: Cmd('git') failed due to: exit code(128)
  cmdline: git add -A
  stderr: 'error: '.autocommit-pro/' does not have a commit checked out
fatal: adding files failed'
[2025-08-17 23:10:15.652] DEBUG    [ThreadPoolExecutor-0_0] logger:debug:362 - Processing 1 file changes
[2025-08-17 23:10:15.657] INFO     [ThreadPoolExecutor-0_0] logger:info:366 - Starting auto-commit for 3 changed files
[2025-08-17 23:10:17.554] ERROR    [ThreadPoolExecutor-0_0] logger:error:380 - Failed to add files to staging
Exception: Traceback (most recent call last):
  File "/Users/arif/Desktop/auto_commit_programs/hadi/.autocommit-pro/auto_git_manager.py", line 120, in add_files
    self.repo.git.add(A=True)
  File "/Users/arif/anaconda3/lib/python3.10/site-packages/git/cmd.py", line 1003, in <lambda>
    return lambda *args, **kwargs: self._call_process(name, *args, **kwargs)
  File "/Users/arif/anaconda3/lib/python3.10/site-packages/git/cmd.py", line 1616, in _call_process
    return self.execute(call, **exec_kwargs)
  File "/Users/arif/anaconda3/lib/python3.10/site-packages/git/cmd.py", line 1406, in execute
    raise GitCommandError(redacted_command, status, stderr_value, stdout_value)
git.exc.GitCommandError: Cmd('git') failed due to: exit code(128)
  cmdline: git add -A
  stderr: 'error: '.autocommit-pro/' does not have a commit checked out
fatal: adding files failed'

[2025-08-17 23:10:17.562] ERROR    [ThreadPoolExecutor-0_0] logger:error:380 - Auto-commit failed: Failed to add files: Cmd('git') failed due to: exit code(128)
  cmdline: git add -A
  stderr: 'error: '.autocommit-pro/' does not have a commit checked out
fatal: adding files failed'
[2025-08-17 23:10:20.658] DEBUG    [ThreadPoolExecutor-0_0] logger:debug:362 - Processing 1 file changes
[2025-08-17 23:10:20.668] INFO     [ThreadPoolExecutor-0_0] logger:info:366 - Starting auto-commit for 4 changed files
[2025-08-17 23:10:22.892] ERROR    [ThreadPoolExecutor-0_0] logger:error:380 - Failed to add files to staging
Exception: Traceback (most recent call last):
  File "/Users/arif/Desktop/auto_commit_programs/hadi/.autocommit-pro/auto_git_manager.py", line 120, in add_files
    self.repo.git.add(A=True)
  File "/Users/arif/anaconda3/lib/python3.10/site-packages/git/cmd.py", line 1003, in <lambda>
    return lambda *args, **kwargs: self._call_process(name, *args, **kwargs)
  File "/Users/arif/anaconda3/lib/python3.10/site-packages/git/cmd.py", line 1616, in _call_process
    return self.execute(call, **exec_kwargs)
  File "/Users/arif/anaconda3/lib/python3.10/site-packages/git/cmd.py", line 1406, in execute
    raise GitCommandError(redacted_command, status, stderr_value, stdout_value)
git.exc.GitCommandError: Cmd('git') failed due to: exit code(128)
  cmdline: git add -A
  stderr: 'error: '.autocommit-pro/' does not have a commit checked out
fatal: adding files failed'

[2025-08-17 23:10:22.904] ERROR    [ThreadPoolExecutor-0_0] logger:error:380 - Auto-commit failed: Failed to add files: Cmd('git') failed due to: exit code(128)
  cmdline: git add -A
  stderr: 'error: '.autocommit-pro/' does not have a commit checked out
fatal: adding files failed'
[2025-08-17 23:10:25.658] DEBUG    [ThreadPoolExecutor-0_0] logger:debug:362 - Processing 1 file changes
[2025-08-17 23:10:25.664] INFO     [ThreadPoolExecutor-0_0] logger:info:366 - Starting auto-commit for 5 changed files
[2025-08-17 23:10:27.607] ERROR    [ThreadPoolExecutor-0_0] logger:error:380 - Failed to add files to staging
Exception: Traceback (most recent call last):
  File "/Users/arif/Desktop/auto_commit_programs/hadi/.autocommit-pro/auto_git_manager.py", line 120, in add_files
    self.repo.git.add(A=True)
  File "/Users/arif/anaconda3/lib/python3.10/site-packages/git/cmd.py", line 1003, in <lambda>
    return lambda *args, **kwargs: self._call_process(name, *args, **kwargs)
  File "/Users/arif/anaconda3/lib/python3.10/site-packages/git/cmd.py", line 1616, in _call_process
    return self.execute(call, **exec_kwargs)
  File "/Users/arif/anaconda3/lib/python3.10/site-packages/git/cmd.py", line 1406, in execute
    raise GitCommandError(redacted_command, status, stderr_value, stdout_value)
git.exc.GitCommandError: Cmd('git') failed due to: exit code(128)
  cmdline: git add -A
  stderr: 'error: '.autocommit-pro/' does not have a commit checked out
fatal: adding files failed'

[2025-08-17 23:10:27.619] ERROR    [ThreadPoolExecutor-0_0] logger:error:380 - Auto-commit failed: Failed to add files: Cmd('git') failed due to: exit code(128)
  cmdline: git add -A
  stderr: 'error: '.autocommit-pro/' does not have a commit checked out
fatal: adding files failed'
[2025-08-17 23:10:34.847] DEBUG    [ThreadPoolExecutor-0_0] logger:debug:362 - Processing 1 file changes
[2025-08-17 23:10:34.852] INFO     [ThreadPoolExecutor-0_0] logger:info:366 - Starting auto-commit for 6 changed files
[2025-08-17 23:10:36.739] ERROR    [ThreadPoolExecutor-0_0] logger:error:380 - Failed to add files to staging
Exception: Traceback (most recent call last):
  File "/Users/arif/Desktop/auto_commit_programs/hadi/.autocommit-pro/auto_git_manager.py", line 120, in add_files
    self.repo.git.add(A=True)
  File "/Users/arif/anaconda3/lib/python3.10/site-packages/git/cmd.py", line 1003, in <lambda>
    return lambda *args, **kwargs: self._call_process(name, *args, **kwargs)
  File "/Users/arif/anaconda3/lib/python3.10/site-packages/git/cmd.py", line 1616, in _call_process
    return self.execute(call, **exec_kwargs)
  File "/Users/arif/anaconda3/lib/python3.10/site-packages/git/cmd.py", line 1406, in execute
    raise GitCommandError(redacted_command, status, stderr_value, stdout_value)
git.exc.GitCommandError: Cmd('git') failed due to: exit code(128)
  cmdline: git add -A
  stderr: 'error: '.autocommit-pro/' does not have a commit checked out
fatal: adding files failed'

[2025-08-17 23:10:36.751] ERROR    [ThreadPoolExecutor-0_0] logger:error:380 - Auto-commit failed: Failed to add files: Cmd('git') failed due to: exit code(128)
  cmdline: git add -A
  stderr: 'error: '.autocommit-pro/' does not have a commit checked out
fatal: adding files failed'
[2025-08-17 23:10:48.910] INFO     [MainThread] logger:info:366 - ðŸ›‘ Stopping AutoGitManager...
[2025-08-17 23:10:48.915] INFO     [MainThread] logger:info:366 - Committing pending changes before shutdown...
[2025-08-17 23:10:48.920] INFO     [MainThread] logger:info:366 - Starting auto-commit for 6 changed files
[2025-08-17 23:10:50.641] ERROR    [MainThread] logger:error:380 - Failed to create commit
Exception: Traceback (most recent call last):
  File "/Users/arif/Desktop/auto_commit_programs/hadi/.autocommit-pro/auto_git_manager.py", line 142, in commit
    if not self.repo.index.diff("HEAD"):
  File "/Users/arif/anaconda3/lib/python3.10/site-packages/git/index/base.py", line 1517, in diff
    other = self.repo.rev_parse(other)
  File "/Users/arif/anaconda3/lib/python3.10/site-packages/git/repo/fun.py", line 415, in rev_parse
    obj = name_to_object(repo, rev)
  File "/Users/arif/anaconda3/lib/python3.10/site-packages/git/repo/fun.py", line 205, in name_to_object
    return Object.new_from_sha(repo, hex_to_bin(hexsha))
  File "/Users/arif/anaconda3/lib/python3.10/site-packages/git/objects/base.py", line 149, in new_from_sha
    oinfo = repo.odb.info(sha1)
  File "/Users/arif/anaconda3/lib/python3.10/site-packages/git/db.py", line 41, in info
    hexsha, typename, size = self._git.get_object_header(bin_to_hex(binsha))
  File "/Users/arif/anaconda3/lib/python3.10/site-packages/git/cmd.py", line 1696, in get_object_header
    return self.__get_object_header(cmd, ref)
  File "/Users/arif/anaconda3/lib/python3.10/site-packages/git/cmd.py", line 1679, in __get_object_header
    cmd.stdin.flush()
BrokenPipeError: [Errno 32] Broken pipe

[2025-08-17 23:10:50.653] ERROR    [MainThread] logger:error:380 - Auto-commit failed: Commit failed: [Errno 32] Broken pipe
[2025-08-17 23:10:50.666] INFO     [MainThread] logger:info:366 - Final push before shutdown...
[2025-08-17 23:10:50.670] INFO     [MainThread] logger:info:366 - Starting auto-push to remote repository
[2025-08-17 23:10:50.746] ERROR    [MainThread] logger:error:380 - Failed to get repository status
Exception: Traceback (most recent call last):
  File "/Users/arif/Desktop/auto_commit_programs/hadi/.autocommit-pro/auto_git_manager.py", line 85, in get_status
    'staged_files': [item.a_path for item in self.repo.index.diff("HEAD")],
  File "/Users/arif/anaconda3/lib/python3.10/site-packages/git/index/base.py", line 1517, in diff
    other = self.repo.rev_parse(other)
  File "/Users/arif/anaconda3/lib/python3.10/site-packages/git/repo/fun.py", line 415, in rev_parse
    obj = name_to_object(repo, rev)
  File "/Users/arif/anaconda3/lib/python3.10/site-packages/git/repo/fun.py", line 205, in name_to_object
    return Object.new_from_sha(repo, hex_to_bin(hexsha))
  File "/Users/arif/anaconda3/lib/python3.10/site-packages/git/objects/base.py", line 149, in new_from_sha
    oinfo = repo.odb.info(sha1)
  File "/Users/arif/anaconda3/lib/python3.10/site-packages/git/db.py", line 41, in info
    hexsha, typename, size = self._git.get_object_header(bin_to_hex(binsha))
  File "/Users/arif/anaconda3/lib/python3.10/site-packages/git/cmd.py", line 1696, in get_object_header
    return self.__get_object_header(cmd, ref)
  File "/Users/arif/anaconda3/lib/python3.10/site-packages/git/cmd.py", line 1679, in __get_object_header
    cmd.stdin.flush()
BrokenPipeError: [Errno 32] Broken pipe

[2025-08-17 23:10:50.761] WARNING  [MainThread] logger:warning:374 - Auto-push failed: No commits to push
[2025-08-17 23:10:50.767] SUCCESS  [MainThread] logger:success:370 - AutoGitManager stopped successfully!
[2025-08-17 23:11:16.091] INFO     [MainThread] logger:info:366 - Connected to git repository: /Users/arif/Desktop/auto_commit_programs/hadi
[2025-08-17 23:11:16.095] INFO     [MainThread] logger:info:366 - File monitoring callback registered
[2025-08-17 23:11:16.098] INFO     [MainThread] logger:info:366 - Scheduled tasks configured
[2025-08-17 23:11:16.100] INFO     [MainThread] logger:info:366 - AutoGitManager initialized for: /Users/arif/Desktop/auto_commit_programs/hadi
[2025-08-17 23:11:16.102] INFO     [MainThread] logger:info:366 - ðŸš€ Starting AutoGitManager...
[2025-08-17 23:11:18.117] INFO     [MainThread] logger:info:366 - Repository status: Branch=main, Dirty=False
[2025-08-17 23:11:18.122] INFO     [MainThread] logger:info:366 - Scheduler thread started
[2025-08-17 23:11:18.123] SUCCESS  [MainThread] logger:success:370 - AutoGitManager started successfully!
[2025-08-17 23:11:34.121] DEBUG    [ThreadPoolExecutor-0_0] logger:debug:362 - Processing 1 file changes
[2025-08-17 23:11:34.126] INFO     [ThreadPoolExecutor-0_0] logger:info:366 - Starting auto-commit for 1 changed files
[2025-08-17 23:11:36.148] ERROR    [ThreadPoolExecutor-0_0] logger:error:380 - Failed to add files to staging
Exception: Traceback (most recent call last):
  File "/Users/arif/Desktop/auto_commit_programs/hadi/.autocommit-pro/auto_git_manager.py", line 120, in add_files
    self.repo.git.add(A=True)
  File "/Users/arif/anaconda3/lib/python3.10/site-packages/git/cmd.py", line 1003, in <lambda>
    return lambda *args, **kwargs: self._call_process(name, *args, **kwargs)
  File "/Users/arif/anaconda3/lib/python3.10/site-packages/git/cmd.py", line 1616, in _call_process
    return self.execute(call, **exec_kwargs)
  File "/Users/arif/anaconda3/lib/python3.10/site-packages/git/cmd.py", line 1406, in execute
    raise GitCommandError(redacted_command, status, stderr_value, stdout_value)
git.exc.GitCommandError: Cmd('git') failed due to: exit code(128)
  cmdline: git add -A
  stderr: 'error: '.autocommit-pro/' does not have a commit checked out
fatal: adding files failed'

[2025-08-17 23:11:36.161] ERROR    [ThreadPoolExecutor-0_0] logger:error:380 - Auto-commit failed: Failed to add files: Cmd('git') failed due to: exit code(128)
  cmdline: git add -A
  stderr: 'error: '.autocommit-pro/' does not have a commit checked out
fatal: adding files failed'
[2025-08-17 23:11:40.141] DEBUG    [ThreadPoolExecutor-0_0] logger:debug:362 - Processing 1 file changes
[2025-08-17 23:11:40.156] INFO     [ThreadPoolExecutor-0_0] logger:info:366 - Starting auto-commit for 2 changed files
[2025-08-17 23:11:42.206] ERROR    [ThreadPoolExecutor-0_0] logger:error:380 - Failed to add files to staging
Exception: Traceback (most recent call last):
  File "/Users/arif/Desktop/auto_commit_programs/hadi/.autocommit-pro/auto_git_manager.py", line 120, in add_files
    self.repo.git.add(A=True)
  File "/Users/arif/anaconda3/lib/python3.10/site-packages/git/cmd.py", line 1003, in <lambda>
    return lambda *args, **kwargs: self._call_process(name, *args, **kwargs)
  File "/Users/arif/anaconda3/lib/python3.10/site-packages/git/cmd.py", line 1616, in _call_process
    return self.execute(call, **exec_kwargs)
  File "/Users/arif/anaconda3/lib/python3.10/site-packages/git/cmd.py", line 1406, in execute
    raise GitCommandError(redacted_command, status, stderr_value, stdout_value)
git.exc.GitCommandError: Cmd('git') failed due to: exit code(128)
  cmdline: git add -A
  stderr: 'error: '.autocommit-pro/' does not have a commit checked out
fatal: adding files failed'

[2025-08-17 23:11:42.215] ERROR    [ThreadPoolExecutor-0_0] logger:error:380 - Auto-commit failed: Failed to add files: Cmd('git') failed due to: exit code(128)
  cmdline: git add -A
  stderr: 'error: '.autocommit-pro/' does not have a commit checked out
fatal: adding files failed'
[2025-08-17 23:12:00.844] DEBUG    [ThreadPoolExecutor-0_0] logger:debug:362 - Processing 1 file changes
[2025-08-17 23:12:00.852] INFO     [ThreadPoolExecutor-0_0] logger:info:366 - Starting auto-commit for 3 changed files
[2025-08-17 23:12:02.627] ERROR    [ThreadPoolExecutor-0_0] logger:error:380 - Failed to add files to staging
Exception: Traceback (most recent call last):
  File "/Users/arif/Desktop/auto_commit_programs/hadi/.autocommit-pro/auto_git_manager.py", line 120, in add_files
    self.repo.git.add(A=True)
  File "/Users/arif/anaconda3/lib/python3.10/site-packages/git/cmd.py", line 1003, in <lambda>
    return lambda *args, **kwargs: self._call_process(name, *args, **kwargs)
  File "/Users/arif/anaconda3/lib/python3.10/site-packages/git/cmd.py", line 1616, in _call_process
    return self.execute(call, **exec_kwargs)
  File "/Users/arif/anaconda3/lib/python3.10/site-packages/git/cmd.py", line 1406, in execute
    raise GitCommandError(redacted_command, status, stderr_value, stdout_value)
git.exc.GitCommandError: Cmd('git') failed due to: exit code(128)
  cmdline: git add -A
  stderr: 'error: '.autocommit-pro/' does not have a commit checked out
fatal: adding files failed'

[2025-08-17 23:12:02.636] ERROR    [ThreadPoolExecutor-0_0] logger:error:380 - Auto-commit failed: Failed to add files: Cmd('git') failed due to: exit code(128)
  cmdline: git add -A
  stderr: 'error: '.autocommit-pro/' does not have a commit checked out
fatal: adding files failed'
[2025-08-17 23:12:03.899] INFO     [MainThread] logger:info:366 - ðŸ›‘ Stopping AutoGitManager...
[2025-08-17 23:12:03.905] INFO     [MainThread] logger:info:366 - Committing pending changes before shutdown...
[2025-08-17 23:12:03.910] INFO     [MainThread] logger:info:366 - Starting auto-commit for 3 changed files
[2025-08-17 23:12:04.018] ERROR    [Thread-14 (scheduler_loop)] logger:error:380 - Failed to get repository status
Exception: Traceback (most recent call last):
  File "/Users/arif/Desktop/auto_commit_programs/hadi/.autocommit-pro/auto_git_manager.py", line 85, in get_status
    'staged_files': [item.a_path for item in self.repo.index.diff("HEAD")],
  File "/Users/arif/anaconda3/lib/python3.10/site-packages/git/index/base.py", line 1517, in diff
    other = self.repo.rev_parse(other)
  File "/Users/arif/anaconda3/lib/python3.10/site-packages/git/repo/fun.py", line 415, in rev_parse
    obj = name_to_object(repo, rev)
  File "/Users/arif/anaconda3/lib/python3.10/site-packages/git/repo/fun.py", line 205, in name_to_object
    return Object.new_from_sha(repo, hex_to_bin(hexsha))
  File "/Users/arif/anaconda3/lib/python3.10/site-packages/git/objects/base.py", line 149, in new_from_sha
    oinfo = repo.odb.info(sha1)
  File "/Users/arif/anaconda3/lib/python3.10/site-packages/git/db.py", line 41, in info
    hexsha, typename, size = self._git.get_object_header(bin_to_hex(binsha))
  File "/Users/arif/anaconda3/lib/python3.10/site-packages/git/cmd.py", line 1696, in get_object_header
    return self.__get_object_header(cmd, ref)
  File "/Users/arif/anaconda3/lib/python3.10/site-packages/git/cmd.py", line 1679, in __get_object_header
    cmd.stdin.flush()
BrokenPipeError: [Errno 32] Broken pipe

[2025-08-17 23:12:41.407] INFO     [MainThread] logger:info:366 - Connected to git repository: /Users/arif/Desktop/auto_commit_programs/hadi
[2025-08-17 23:12:41.412] INFO     [MainThread] logger:info:366 - File monitoring callback registered
[2025-08-17 23:12:41.415] INFO     [MainThread] logger:info:366 - Scheduled tasks configured
[2025-08-17 23:12:41.417] INFO     [MainThread] logger:info:366 - AutoGitManager initialized for: /Users/arif/Desktop/auto_commit_programs/hadi
[2025-08-17 23:12:41.418] INFO     [MainThread] logger:info:366 - ðŸš€ Starting AutoGitManager...
[2025-08-17 23:12:43.434] INFO     [MainThread] logger:info:366 - Repository status: Branch=main, Dirty=False
[2025-08-17 23:12:43.441] INFO     [MainThread] logger:info:366 - Scheduler thread started
[2025-08-17 23:12:43.442] SUCCESS  [MainThread] logger:success:370 - AutoGitManager started successfully!
[2025-08-17 23:12:57.495] DEBUG    [ThreadPoolExecutor-0_0] logger:debug:362 - Processing 1 file changes
[2025-08-17 23:12:57.500] INFO     [ThreadPoolExecutor-0_0] logger:info:366 - Starting auto-commit for 1 changed files
[2025-08-17 23:12:59.651] ERROR    [ThreadPoolExecutor-0_0] logger:error:380 - Failed to add files to staging
Exception: Traceback (most recent call last):
  File "/Users/arif/Desktop/auto_commit_programs/hadi/.autocommit-pro/auto_git_manager.py", line 120, in add_files
    self.repo.git.add(A=True)
  File "/Users/arif/anaconda3/lib/python3.10/site-packages/git/cmd.py", line 1003, in <lambda>
    return lambda *args, **kwargs: self._call_process(name, *args, **kwargs)
  File "/Users/arif/anaconda3/lib/python3.10/site-packages/git/cmd.py", line 1616, in _call_process
    return self.execute(call, **exec_kwargs)
  File "/Users/arif/anaconda3/lib/python3.10/site-packages/git/cmd.py", line 1406, in execute
    raise GitCommandError(redacted_command, status, stderr_value, stdout_value)
git.exc.GitCommandError: Cmd('git') failed due to: exit code(128)
  cmdline: git add -A
  stderr: 'error: '.autocommit-pro/' does not have a commit checked out
fatal: adding files failed'

[2025-08-17 23:12:59.660] ERROR    [ThreadPoolExecutor-0_0] logger:error:380 - Auto-commit failed: Failed to add files: Cmd('git') failed due to: exit code(128)
  cmdline: git add -A
  stderr: 'error: '.autocommit-pro/' does not have a commit checked out
fatal: adding files failed'
[2025-08-17 23:13:09.885] INFO     [MainThread] logger:info:366 - ðŸ›‘ Stopping AutoGitManager...
[2025-08-17 23:13:09.890] INFO     [MainThread] logger:info:366 - Committing pending changes before shutdown...
[2025-08-17 23:13:09.894] INFO     [MainThread] logger:info:366 - Starting auto-commit for 1 changed files
[2025-08-17 23:13:09.897] ERROR    [Thread-14 (scheduler_loop)] logger:error:380 - Failed to get repository status
Exception: Traceback (most recent call last):
  File "/Users/arif/Desktop/auto_commit_programs/hadi/.autocommit-pro/auto_git_manager.py", line 88, in get_status
    'hash': self.repo.head.commit.hexsha[:8],
  File "/Users/arif/anaconda3/lib/python3.10/site-packages/git/refs/symbolic.py", line 392, in commit
    return self._get_commit()
  File "/Users/arif/anaconda3/lib/python3.10/site-packages/git/refs/symbolic.py", line 296, in _get_commit
    obj = self._get_object()
  File "/Users/arif/anaconda3/lib/python3.10/site-packages/git/refs/symbolic.py", line 287, in _get_object
    return Object.new_from_sha(self.repo, hex_to_bin(self.dereference_recursive(self.repo, self.path)))
  File "/Users/arif/anaconda3/lib/python3.10/site-packages/git/objects/base.py", line 149, in new_from_sha
    oinfo = repo.odb.info(sha1)
  File "/Users/arif/anaconda3/lib/python3.10/site-packages/git/db.py", line 41, in info
    hexsha, typename, size = self._git.get_object_header(bin_to_hex(binsha))
  File "/Users/arif/anaconda3/lib/python3.10/site-packages/git/cmd.py", line 1696, in get_object_header
    return self.__get_object_header(cmd, ref)
  File "/Users/arif/anaconda3/lib/python3.10/site-packages/git/cmd.py", line 1679, in __get_object_header
    cmd.stdin.flush()
BrokenPipeError: [Errno 32] Broken pipe

[2025-08-17 23:13:11.907] ERROR    [MainThread] logger:error:380 - Failed to create commit
Exception: Traceback (most recent call last):
  File "/Users/arif/Desktop/auto_commit_programs/hadi/.autocommit-pro/auto_git_manager.py", line 142, in commit
    if not self.repo.index.diff("HEAD"):
  File "/Users/arif/anaconda3/lib/python3.10/site-packages/git/index/base.py", line 1517, in diff
    other = self.repo.rev_parse(other)
  File "/Users/arif/anaconda3/lib/python3.10/site-packages/git/repo/fun.py", line 415, in rev_parse
    obj = name_to_object(repo, rev)
  File "/Users/arif/anaconda3/lib/python3.10/site-packages/git/repo/fun.py", line 205, in name_to_object
    return Object.new_from_sha(repo, hex_to_bin(hexsha))
  File "/Users/arif/anaconda3/lib/python3.10/site-packages/git/objects/base.py", line 149, in new_from_sha
    oinfo = repo.odb.info(sha1)
  File "/Users/arif/anaconda3/lib/python3.10/site-packages/git/db.py", line 41, in info
    hexsha, typename, size = self._git.get_object_header(bin_to_hex(binsha))
  File "/Users/arif/anaconda3/lib/python3.10/site-packages/git/cmd.py", line 1696, in get_object_header
    return self.__get_object_header(cmd, ref)
  File "/Users/arif/anaconda3/lib/python3.10/site-packages/git/cmd.py", line 1679, in __get_object_header
    cmd.stdin.flush()
BrokenPipeError: [Errno 32] Broken pipe

[2025-08-17 23:13:11.917] ERROR    [MainThread] logger:error:380 - Auto-commit failed: Commit failed: [Errno 32] Broken pipe
[2025-08-17 23:13:11.933] INFO     [MainThread] logger:info:366 - Final push before shutdown...
[2025-08-17 23:13:11.937] INFO     [MainThread] logger:info:366 - Starting auto-push to remote repository
[2025-08-17 23:13:12.010] ERROR    [MainThread] logger:error:380 - Failed to get repository status
Exception: Traceback (most recent call last):
  File "/Users/arif/Desktop/auto_commit_programs/hadi/.autocommit-pro/auto_git_manager.py", line 85, in get_status
    'staged_files': [item.a_path for item in self.repo.index.diff("HEAD")],
  File "/Users/arif/anaconda3/lib/python3.10/site-packages/git/index/base.py", line 1517, in diff
    other = self.repo.rev_parse(other)
  File "/Users/arif/anaconda3/lib/python3.10/site-packages/git/repo/fun.py", line 415, in rev_parse
    obj = name_to_object(repo, rev)
  File "/Users/arif/anaconda3/lib/python3.10/site-packages/git/repo/fun.py", line 205, in name_to_object
    return Object.new_from_sha(repo, hex_to_bin(hexsha))
  File "/Users/arif/anaconda3/lib/python3.10/site-packages/git/objects/base.py", line 149, in new_from_sha
    oinfo = repo.odb.info(sha1)
  File "/Users/arif/anaconda3/lib/python3.10/site-packages/git/db.py", line 41, in info
    hexsha, typename, size = self._git.get_object_header(bin_to_hex(binsha))
  File "/Users/arif/anaconda3/lib/python3.10/site-packages/git/cmd.py", line 1696, in get_object_header
    return self.__get_object_header(cmd, ref)
  File "/Users/arif/anaconda3/lib/python3.10/site-packages/git/cmd.py", line 1679, in __get_object_header
    cmd.stdin.flush()
BrokenPipeError: [Errno 32] Broken pipe

[2025-08-17 23:13:12.019] WARNING  [MainThread] logger:warning:374 - Auto-push failed: No commits to push
[2025-08-17 23:13:12.024] SUCCESS  [MainThread] logger:success:370 - AutoGitManager stopped successfully!
[2025-08-17 23:13:44.749] INFO     [MainThread] logger:info:366 - Connected to git repository: /Users/arif/Desktop/auto_commit_programs/hadi
[2025-08-17 23:13:44.753] INFO     [MainThread] logger:info:366 - File monitoring callback registered
[2025-08-17 23:13:44.756] INFO     [MainThread] logger:info:366 - Scheduled tasks configured
[2025-08-17 23:13:44.758] INFO     [MainThread] logger:info:366 - AutoGitManager initialized for: /Users/arif/Desktop/auto_commit_programs/hadi
[2025-08-17 23:13:44.760] INFO     [MainThread] logger:info:366 - ðŸš€ Starting AutoGitManager...
[2025-08-17 23:13:46.942] INFO     [MainThread] logger:info:366 - Repository status: Branch=main, Dirty=False
[2025-08-17 23:13:46.949] INFO     [MainThread] logger:info:366 - Scheduler thread started
[2025-08-17 23:13:46.950] SUCCESS  [MainThread] logger:success:370 - AutoGitManager started successfully!
[2025-08-17 23:14:08.802] DEBUG    [ThreadPoolExecutor-0_0] logger:debug:362 - Processing 1 file changes
[2025-08-17 23:14:08.807] INFO     [ThreadPoolExecutor-0_0] logger:info:366 - Starting auto-commit for 1 changed files
[2025-08-17 23:14:11.166] ERROR    [ThreadPoolExecutor-0_0] logger:error:380 - Failed to add files to staging
Exception: Traceback (most recent call last):
  File "/Users/arif/Desktop/auto_commit_programs/hadi/.autocommit-pro/auto_git_manager.py", line 120, in add_files
    self.repo.git.add(A=True)
  File "/Users/arif/anaconda3/lib/python3.10/site-packages/git/cmd.py", line 1003, in <lambda>
    return lambda *args, **kwargs: self._call_process(name, *args, **kwargs)
  File "/Users/arif/anaconda3/lib/python3.10/site-packages/git/cmd.py", line 1616, in _call_process
    return self.execute(call, **exec_kwargs)
  File "/Users/arif/anaconda3/lib/python3.10/site-packages/git/cmd.py", line 1406, in execute
    raise GitCommandError(redacted_command, status, stderr_value, stdout_value)
git.exc.GitCommandError: Cmd('git') failed due to: exit code(128)
  cmdline: git add -A
  stderr: 'error: '.autocommit-pro/' does not have a commit checked out
fatal: adding files failed'

[2025-08-17 23:14:11.174] ERROR    [ThreadPoolExecutor-0_0] logger:error:380 - Auto-commit failed: Failed to add files: Cmd('git') failed due to: exit code(128)
  cmdline: git add -A
  stderr: 'error: '.autocommit-pro/' does not have a commit checked out
fatal: adding files failed'
[2025-08-17 23:14:15.237] DEBUG    [ThreadPoolExecutor-0_0] logger:debug:362 - Processing 1 file changes
[2025-08-17 23:14:15.241] INFO     [ThreadPoolExecutor-0_0] logger:info:366 - Starting auto-commit for 1 changed files
[2025-08-17 23:14:17.228] ERROR    [ThreadPoolExecutor-0_0] logger:error:380 - Failed to add files to staging
Exception: Traceback (most recent call last):
  File "/Users/arif/Desktop/auto_commit_programs/hadi/.autocommit-pro/auto_git_manager.py", line 120, in add_files
    self.repo.git.add(A=True)
  File "/Users/arif/anaconda3/lib/python3.10/site-packages/git/cmd.py", line 1003, in <lambda>
    return lambda *args, **kwargs: self._call_process(name, *args, **kwargs)
  File "/Users/arif/anaconda3/lib/python3.10/site-packages/git/cmd.py", line 1616, in _call_process
    return self.execute(call, **exec_kwargs)
  File "/Users/arif/anaconda3/lib/python3.10/site-packages/git/cmd.py", line 1406, in execute
    raise GitCommandError(redacted_command, status, stderr_value, stdout_value)
git.exc.GitCommandError: Cmd('git') failed due to: exit code(128)
  cmdline: git add -A
  stderr: 'error: '.autocommit-pro/' does not have a commit checked out
fatal: adding files failed'

[2025-08-17 23:14:17.241] ERROR    [ThreadPoolExecutor-0_0] logger:error:380 - Auto-commit failed: Failed to add files: Cmd('git') failed due to: exit code(128)
  cmdline: git add -A
  stderr: 'error: '.autocommit-pro/' does not have a commit checked out
fatal: adding files failed'
[2025-08-17 23:14:22.195] INFO     [MainThread] logger:info:366 - ðŸ›‘ Stopping AutoGitManager...
[2025-08-17 23:14:22.199] INFO     [MainThread] logger:info:366 - Committing pending changes before shutdown...
[2025-08-17 23:14:22.203] INFO     [MainThread] logger:info:366 - Starting auto-commit for 1 changed files
[2025-08-17 23:14:24.232] ERROR    [MainThread] logger:error:380 - Failed to create commit
Exception: Traceback (most recent call last):
  File "/Users/arif/Desktop/auto_commit_programs/hadi/.autocommit-pro/auto_git_manager.py", line 142, in commit
    if not self.repo.index.diff("HEAD"):
  File "/Users/arif/anaconda3/lib/python3.10/site-packages/git/index/base.py", line 1517, in diff
    other = self.repo.rev_parse(other)
  File "/Users/arif/anaconda3/lib/python3.10/site-packages/git/repo/fun.py", line 415, in rev_parse
    obj = name_to_object(repo, rev)
  File "/Users/arif/anaconda3/lib/python3.10/site-packages/git/repo/fun.py", line 205, in name_to_object
    return Object.new_from_sha(repo, hex_to_bin(hexsha))
  File "/Users/arif/anaconda3/lib/python3.10/site-packages/git/objects/base.py", line 149, in new_from_sha
    oinfo = repo.odb.info(sha1)
  File "/Users/arif/anaconda3/lib/python3.10/site-packages/git/db.py", line 41, in info
    hexsha, typename, size = self._git.get_object_header(bin_to_hex(binsha))
  File "/Users/arif/anaconda3/lib/python3.10/site-packages/git/cmd.py", line 1696, in get_object_header
    return self.__get_object_header(cmd, ref)
  File "/Users/arif/anaconda3/lib/python3.10/site-packages/git/cmd.py", line 1679, in __get_object_header
    cmd.stdin.flush()
BrokenPipeError: [Errno 32] Broken pipe

[2025-08-17 23:14:24.241] ERROR    [MainThread] logger:error:380 - Auto-commit failed: Commit failed: [Errno 32] Broken pipe
[2025-08-17 23:14:24.253] INFO     [MainThread] logger:info:366 - Final push before shutdown...
[2025-08-17 23:14:24.256] INFO     [MainThread] logger:info:366 - Starting auto-push to remote repository
[2025-08-17 23:14:24.331] ERROR    [MainThread] logger:error:380 - Failed to get repository status
Exception: Traceback (most recent call last):
  File "/Users/arif/Desktop/auto_commit_programs/hadi/.autocommit-pro/auto_git_manager.py", line 85, in get_status
    'staged_files': [item.a_path for item in self.repo.index.diff("HEAD")],
  File "/Users/arif/anaconda3/lib/python3.10/site-packages/git/index/base.py", line 1517, in diff
    other = self.repo.rev_parse(other)
  File "/Users/arif/anaconda3/lib/python3.10/site-packages/git/repo/fun.py", line 415, in rev_parse
    obj = name_to_object(repo, rev)
  File "/Users/arif/anaconda3/lib/python3.10/site-packages/git/repo/fun.py", line 205, in name_to_object
    return Object.new_from_sha(repo, hex_to_bin(hexsha))
  File "/Users/arif/anaconda3/lib/python3.10/site-packages/git/objects/base.py", line 149, in new_from_sha
    oinfo = repo.odb.info(sha1)
  File "/Users/arif/anaconda3/lib/python3.10/site-packages/git/db.py", line 41, in info
    hexsha, typename, size = self._git.get_object_header(bin_to_hex(binsha))
  File "/Users/arif/anaconda3/lib/python3.10/site-packages/git/cmd.py", line 1696, in get_object_header
    return self.__get_object_header(cmd, ref)
  File "/Users/arif/anaconda3/lib/python3.10/site-packages/git/cmd.py", line 1679, in __get_object_header
    cmd.stdin.flush()
BrokenPipeError: [Errno 32] Broken pipe

[2025-08-17 23:14:24.341] WARNING  [MainThread] logger:warning:374 - Auto-push failed: No commits to push
[2025-08-17 23:14:24.345] SUCCESS  [MainThread] logger:success:370 - AutoGitManager stopped successfully!
[2025-08-17 23:15:31.060] INFO     [MainThread] logger:info:366 - Connected to git repository: /Users/arif/Desktop/auto_commit_programs/hadi
[2025-08-17 23:15:31.062] INFO     [MainThread] logger:info:366 - File monitoring callback registered
[2025-08-17 23:15:31.064] INFO     [MainThread] logger:info:366 - Scheduled tasks configured
[2025-08-17 23:15:31.065] INFO     [MainThread] logger:info:366 - AutoGitManager initialized for: /Users/arif/Desktop/auto_commit_programs/hadi
[2025-08-17 23:15:31.066] INFO     [MainThread] logger:info:366 - ðŸš€ Starting AutoGitManager...
[2025-08-17 23:15:33.069] INFO     [MainThread] logger:info:366 - Repository status: Branch=main, Dirty=False
[2025-08-17 23:15:33.076] INFO     [MainThread] logger:info:366 - Scheduler thread started
[2025-08-17 23:15:33.077] SUCCESS  [MainThread] logger:success:370 - AutoGitManager started successfully!
[2025-08-17 23:15:57.115] DEBUG    [ThreadPoolExecutor-0_0] logger:debug:362 - Processing 1 file changes
[2025-08-17 23:15:57.119] INFO     [ThreadPoolExecutor-0_0] logger:info:366 - Starting auto-commit for 1 changed files
[2025-08-17 23:15:59.393] ERROR    [ThreadPoolExecutor-0_0] logger:error:380 - Failed to add files to staging
Exception: Traceback (most recent call last):
  File "/Users/arif/Desktop/auto_commit_programs/hadi/.autocommit-pro/auto_git_manager.py", line 120, in add_files
    self.repo.git.add(A=True)
  File "/Users/arif/anaconda3/lib/python3.10/site-packages/git/cmd.py", line 1003, in <lambda>
    return lambda *args, **kwargs: self._call_process(name, *args, **kwargs)
  File "/Users/arif/anaconda3/lib/python3.10/site-packages/git/cmd.py", line 1616, in _call_process
    return self.execute(call, **exec_kwargs)
  File "/Users/arif/anaconda3/lib/python3.10/site-packages/git/cmd.py", line 1406, in execute
    raise GitCommandError(redacted_command, status, stderr_value, stdout_value)
git.exc.GitCommandError: Cmd('git') failed due to: exit code(128)
  cmdline: git add -A
  stderr: 'error: '.autocommit-pro/' does not have a commit checked out
fatal: adding files failed'

[2025-08-17 23:15:59.402] ERROR    [ThreadPoolExecutor-0_0] logger:error:380 - Auto-commit failed: Failed to add files: Cmd('git') failed due to: exit code(128)
  cmdline: git add -A
  stderr: 'error: '.autocommit-pro/' does not have a commit checked out
fatal: adding files failed'
[2025-08-17 23:16:03.128] DEBUG    [ThreadPoolExecutor-0_0] logger:debug:362 - Processing 1 file changes
[2025-08-17 23:16:03.135] INFO     [ThreadPoolExecutor-0_0] logger:info:366 - Starting auto-commit for 2 changed files
[2025-08-17 23:16:05.411] ERROR    [ThreadPoolExecutor-0_0] logger:error:380 - Failed to add files to staging
Exception: Traceback (most recent call last):
  File "/Users/arif/Desktop/auto_commit_programs/hadi/.autocommit-pro/auto_git_manager.py", line 120, in add_files
    self.repo.git.add(A=True)
  File "/Users/arif/anaconda3/lib/python3.10/site-packages/git/cmd.py", line 1003, in <lambda>
    return lambda *args, **kwargs: self._call_process(name, *args, **kwargs)
  File "/Users/arif/anaconda3/lib/python3.10/site-packages/git/cmd.py", line 1616, in _call_process
    return self.execute(call, **exec_kwargs)
  File "/Users/arif/anaconda3/lib/python3.10/site-packages/git/cmd.py", line 1406, in execute
    raise GitCommandError(redacted_command, status, stderr_value, stdout_value)
git.exc.GitCommandError: Cmd('git') failed due to: exit code(128)
  cmdline: git add -A
  stderr: 'error: '.autocommit-pro/' does not have a commit checked out
fatal: adding files failed'

[2025-08-17 23:16:05.420] ERROR    [ThreadPoolExecutor-0_0] logger:error:380 - Auto-commit failed: Failed to add files: Cmd('git') failed due to: exit code(128)
  cmdline: git add -A
  stderr: 'error: '.autocommit-pro/' does not have a commit checked out
fatal: adding files failed'
[2025-08-17 23:16:08.110] DEBUG    [ThreadPoolExecutor-0_0] logger:debug:362 - Processing 4 file changes
[2025-08-17 23:16:08.114] INFO     [ThreadPoolExecutor-0_0] logger:info:366 - Starting auto-commit for 6 changed files
[2025-08-17 23:16:10.024] ERROR    [ThreadPoolExecutor-0_0] logger:error:380 - Failed to add files to staging
Exception: Traceback (most recent call last):
  File "/Users/arif/Desktop/auto_commit_programs/hadi/.autocommit-pro/auto_git_manager.py", line 120, in add_files
    self.repo.git.add(A=True)
  File "/Users/arif/anaconda3/lib/python3.10/site-packages/git/cmd.py", line 1003, in <lambda>
    return lambda *args, **kwargs: self._call_process(name, *args, **kwargs)
  File "/Users/arif/anaconda3/lib/python3.10/site-packages/git/cmd.py", line 1616, in _call_process
    return self.execute(call, **exec_kwargs)
  File "/Users/arif/anaconda3/lib/python3.10/site-packages/git/cmd.py", line 1406, in execute
    raise GitCommandError(redacted_command, status, stderr_value, stdout_value)
git.exc.GitCommandError: Cmd('git') failed due to: exit code(128)
  cmdline: git add -A
  stderr: 'error: '.autocommit-pro/' does not have a commit checked out
fatal: adding files failed'

[2025-08-17 23:16:10.033] ERROR    [ThreadPoolExecutor-0_0] logger:error:380 - Auto-commit failed: Failed to add files: Cmd('git') failed due to: exit code(128)
  cmdline: git add -A
  stderr: 'error: '.autocommit-pro/' does not have a commit checked out
fatal: adding files failed'
[2025-08-17 23:16:13.116] DEBUG    [ThreadPoolExecutor-0_0] logger:debug:362 - Processing 1 file changes
[2025-08-17 23:16:13.120] INFO     [ThreadPoolExecutor-0_0] logger:info:366 - Starting auto-commit for 7 changed files
[2025-08-17 23:16:14.565] INFO     [MainThread] logger:info:366 - ðŸ›‘ Stopping AutoGitManager...
[2025-08-17 23:16:14.595] INFO     [MainThread] logger:info:366 - Committing pending changes before shutdown...
[2025-08-17 23:16:14.638] INFO     [MainThread] logger:info:366 - Starting auto-commit for 7 changed files
[2025-08-17 23:16:15.000] ERROR    [ThreadPoolExecutor-0_0] logger:error:380 - Failed to create commit
Exception: Traceback (most recent call last):
  File "/Users/arif/Desktop/auto_commit_programs/hadi/.autocommit-pro/auto_git_manager.py", line 142, in commit
    if not self.repo.index.diff("HEAD"):
  File "/Users/arif/anaconda3/lib/python3.10/site-packages/git/index/base.py", line 1517, in diff
    other = self.repo.rev_parse(other)
  File "/Users/arif/anaconda3/lib/python3.10/site-packages/git/repo/fun.py", line 415, in rev_parse
    obj = name_to_object(repo, rev)
  File "/Users/arif/anaconda3/lib/python3.10/site-packages/git/repo/fun.py", line 205, in name_to_object
    return Object.new_from_sha(repo, hex_to_bin(hexsha))
  File "/Users/arif/anaconda3/lib/python3.10/site-packages/git/objects/base.py", line 149, in new_from_sha
    oinfo = repo.odb.info(sha1)
  File "/Users/arif/anaconda3/lib/python3.10/site-packages/git/db.py", line 41, in info
    hexsha, typename, size = self._git.get_object_header(bin_to_hex(binsha))
  File "/Users/arif/anaconda3/lib/python3.10/site-packages/git/cmd.py", line 1696, in get_object_header
    return self.__get_object_header(cmd, ref)
  File "/Users/arif/anaconda3/lib/python3.10/site-packages/git/cmd.py", line 1679, in __get_object_header
    cmd.stdin.flush()
BrokenPipeError: [Errno 32] Broken pipe

[2025-08-17 23:16:15.016] ERROR    [ThreadPoolExecutor-0_0] logger:error:380 - Auto-commit failed: Commit failed: [Errno 32] Broken pipe
[2025-08-17 23:16:16.598] ERROR    [MainThread] logger:error:380 - Failed to create commit
Exception: Traceback (most recent call last):
  File "/Users/arif/Desktop/auto_commit_programs/hadi/.autocommit-pro/auto_git_manager.py", line 142, in commit
    if not self.repo.index.diff("HEAD"):
  File "/Users/arif/anaconda3/lib/python3.10/site-packages/git/index/base.py", line 1517, in diff
    other = self.repo.rev_parse(other)
  File "/Users/arif/anaconda3/lib/python3.10/site-packages/git/repo/fun.py", line 415, in rev_parse
    obj = name_to_object(repo, rev)
  File "/Users/arif/anaconda3/lib/python3.10/site-packages/git/repo/fun.py", line 205, in name_to_object
    return Object.new_from_sha(repo, hex_to_bin(hexsha))
  File "/Users/arif/anaconda3/lib/python3.10/site-packages/git/objects/base.py", line 149, in new_from_sha
    oinfo = repo.odb.info(sha1)
  File "/Users/arif/anaconda3/lib/python3.10/site-packages/git/db.py", line 41, in info
    hexsha, typename, size = self._git.get_object_header(bin_to_hex(binsha))
  File "/Users/arif/anaconda3/lib/python3.10/site-packages/git/cmd.py", line 1696, in get_object_header
    return self.__get_object_header(cmd, ref)
  File "/Users/arif/anaconda3/lib/python3.10/site-packages/git/cmd.py", line 1679, in __get_object_header
    cmd.stdin.flush()
BrokenPipeError: [Errno 32] Broken pipe

[2025-08-17 23:16:16.608] ERROR    [MainThread] logger:error:380 - Auto-commit failed: Commit failed: [Errno 32] Broken pipe
[2025-08-17 23:16:16.620] INFO     [MainThread] logger:info:366 - Final push before shutdown...
[2025-08-17 23:16:16.624] INFO     [MainThread] logger:info:366 - Starting auto-push to remote repository
[2025-08-17 23:16:16.698] ERROR    [MainThread] logger:error:380 - Failed to get repository status
Exception: Traceback (most recent call last):
  File "/Users/arif/Desktop/auto_commit_programs/hadi/.autocommit-pro/auto_git_manager.py", line 85, in get_status
    'staged_files': [item.a_path for item in self.repo.index.diff("HEAD")],
  File "/Users/arif/anaconda3/lib/python3.10/site-packages/git/index/base.py", line 1517, in diff
    other = self.repo.rev_parse(other)
  File "/Users/arif/anaconda3/lib/python3.10/site-packages/git/repo/fun.py", line 415, in rev_parse
    obj = name_to_object(repo, rev)
  File "/Users/arif/anaconda3/lib/python3.10/site-packages/git/repo/fun.py", line 205, in name_to_object
    return Object.new_from_sha(repo, hex_to_bin(hexsha))
  File "/Users/arif/anaconda3/lib/python3.10/site-packages/git/objects/base.py", line 149, in new_from_sha
    oinfo = repo.odb.info(sha1)
  File "/Users/arif/anaconda3/lib/python3.10/site-packages/git/db.py", line 41, in info
    hexsha, typename, size = self._git.get_object_header(bin_to_hex(binsha))
  File "/Users/arif/anaconda3/lib/python3.10/site-packages/git/cmd.py", line 1696, in get_object_header
    return self.__get_object_header(cmd, ref)
  File "/Users/arif/anaconda3/lib/python3.10/site-packages/git/cmd.py", line 1679, in __get_object_header
    cmd.stdin.flush()
BrokenPipeError: [Errno 32] Broken pipe

[2025-08-17 23:16:16.709] WARNING  [MainThread] logger:warning:374 - Auto-push failed: No commits to push
[2025-08-17 23:16:16.714] SUCCESS  [MainThread] logger:success:370 - AutoGitManager stopped successfully!
